test_test_sum (unit_test.testSum.test_test_sum) ... unit_test.testSum.test_test_sum: 0.000
ok
test_test_sum_fail (unit_test.testSum.test_test_sum_fail) ... FAIL
unit_test.testSum.test_test_sum_fail: 0.000

======================================================================
FAIL: test_test_sum_fail (unit_test.testSum.test_test_sum_fail)
----------------------------------------------------------------------
Traceback (most recent call last):
  File "/testing/student_module/unit_test.py", line 20, in test_test_sum_fail
    self.assertEqual(test_sum(1, 3), 3, "Answer should be 3")
AssertionError: 4 != 3 : Answer should be 3

----------------------------------------------------------------------
Ran 2 tests in 0.002s

FAILED (failures=1)
