test_test_sum (__main__.testCases.test_test_sum) ... ok
test_test_sum_fail (__main__.testCases.test_test_sum_fail) ... FAIL

======================================================================
FAIL: test_test_sum_fail (__main__.testCases.test_test_sum_fail)
----------------------------------------------------------------------
Traceback (most recent call last):
  File "/testing/student_module/./unit_test.py", line 13, in test_test_sum_fail
    self.assertEqual(test_sum(1, 3), 3, "Answer should be 3")
AssertionError: 4 != 3 : Answer should be 3

----------------------------------------------------------------------
Ran 2 tests in 0.002s

FAILED (failures=1)
